<mujoco>
	<option gravity="0 0 -9" viscosity="0.1" wind="0 20 0" />
  <worldbody>
    <light diffuse=".5 .5 .5" pos="0 0 7" dir="0 0 -1"/>
    <geom type="plane" size="1 1 0.1" rgba=".9 0.9 0.9 1"/>
    <body pos="0 0 0.3" euler="0 90 0">
      <joint type="hinge" pos="0 0 0.2" range="5 6" limited="true"/>
      <geom type="cylinder" size="0.025 0.2" rgba="0 .9 0 1" mass="2"/>
			<body pos="0 0 -0.3" euler="0 0 0">
<!--				<joint type="ball" pos="0 0 0.1" limited="true" range="0 30" damping="0.1"/>-->
        <joint type="hinge" pos="0 0 0.1" axis="1 0 0" limited="true" range="0 30" damping="0.1"
               stiffness="0.01"/>
        <joint type="hinge" pos="0 0 0.1" axis="0 1 0" damping="0.1" limited="true" range="0 15"/>
				<geom type="box" size="0.02 0.01 0.1" rgba="0.9 0 0 1" mass="2"/>
			</body>
    </body>
  </worldbody>
</mujoco>
